<?xml version="1.0" encoding="UTF-8"?>
<!-- Generated by org.testng.reporters.JUnitXMLReporter -->
<testsuite hostname="buli" ignored="0" name="ExceptionTest" tests="3" failures="1" timestamp="27 九月 2020 09:39:23 GMT" time="0.031" errors="0">
  <testcase name="arithmeticException" time="0.0" classname="com.trustkernel.kpp.api.testcase.ExceptionTest"/>
  <testcase name="runTimeExceptionFailed" time="0.016" classname="com.trustkernel.kpp.api.testcase.ExceptionTest">
    <failure type="org.testng.TestException" message="
Method ExceptionTest.runTimeExceptionFailed()[pri:0, instance:com.trustkernel.kpp.api.testcase.ExceptionTest@31206beb] should have thrown an exception of type class java.lang.RuntimeException">
      <![CDATA[org.testng.TestException: 
Method ExceptionTest.runTimeExceptionFailed()[pri:0, instance:com.trustkernel.kpp.api.testcase.ExceptionTest@31206beb] should have thrown an exception of type class java.lang.RuntimeException
... Removed 22 stack frames]]>
    </failure>
  </testcase> <!-- runTimeExceptionFailed -->
  <testcase name="runTimeExceptionSuccess" time="0.0" classname="com.trustkernel.kpp.api.testcase.ExceptionTest"/>
</testsuite> <!-- ExceptionTest -->
