<?xml version="1.0" encoding="UTF-8"?>
<!-- Generated by org.testng.reporters.JUnitReportReporter -->
<testsuite skipped="0" hostname="buli" name="com.trustkernel.kpp.api.testcase.ExceptionTest" tests="3" failures="0" timestamp="27 九月 2020 09:39:23 GMT" time="0.016" errors="1">
  <testcase name="arithmeticException" time="0.000" classname="com.trustkernel.kpp.api.testcase.ExceptionTest"/>
  <testcase name="runTimeExceptionSuccess" time="0.000" classname="com.trustkernel.kpp.api.testcase.ExceptionTest"/>
  <testcase name="runTimeExceptionFailed" time="0.016" classname="com.trustkernel.kpp.api.testcase.ExceptionTest">
    <error type="org.testng.TestException" message="
Method ExceptionTest.runTimeExceptionFailed()[pri:0, instance:com.trustkernel.kpp.api.testcase.ExceptionTest@31206beb] should have thrown an exception of type class java.lang.RuntimeException">
      <![CDATA[org.testng.TestException: 
Method ExceptionTest.runTimeExceptionFailed()[pri:0, instance:com.trustkernel.kpp.api.testcase.ExceptionTest@31206beb] should have thrown an exception of type class java.lang.RuntimeException
at org.testng.internal.ExpectedExceptionsHolder.noException(ExpectedExceptionsHolder.java:80)
at org.testng.internal.Invoker.considerExceptions(Invoker.java:1140)
at org.testng.internal.Invoker.invokeMethod(Invoker.java:615)
at org.testng.internal.Invoker.invokeTestMethod(Invoker.java:719)
at org.testng.internal.Invoker.invokeTestMethods(Invoker.java:989)
at org.testng.internal.TestMethodWorker.invokeTestMethods(TestMethodWorker.java:125)
at org.testng.internal.TestMethodWorker.run(TestMethodWorker.java:109)
at org.testng.TestRunner.privateRun(TestRunner.java:648)
at org.testng.TestRunner.run(TestRunner.java:505)
at org.testng.SuiteRunner.runTest(SuiteRunner.java:455)
at org.testng.SuiteRunner.runSequentially(SuiteRunner.java:450)
at org.testng.SuiteRunner.privateRun(SuiteRunner.java:415)
at org.testng.SuiteRunner.run(SuiteRunner.java:364)
at org.testng.SuiteRunnerWorker.runSuite(SuiteRunnerWorker.java:52)
at org.testng.SuiteRunnerWorker.run(SuiteRunnerWorker.java:84)
at org.testng.TestNG.runSuitesSequentially(TestNG.java:1208)
at org.testng.TestNG.runSuitesLocally(TestNG.java:1137)
at org.testng.TestNG.runSuites(TestNG.java:1049)
at org.testng.TestNG.run(TestNG.java:1017)
at org.testng.remote.AbstractRemoteTestNG.run(AbstractRemoteTestNG.java:132)
at org.testng.remote.RemoteTestNG.initAndRun(RemoteTestNG.java:236)
at org.testng.remote.RemoteTestNG.main(RemoteTestNG.java:81)
]]>
    </error>
  </testcase> <!-- runTimeExceptionFailed -->
</testsuite> <!-- com.trustkernel.kpp.api.testcase.ExceptionTest -->
